<?xml version="1.0" encoding="utf-8"?>
<!-- This URDF was automatically created by SolidWorks to URDF Exporter! Originally created by Stephen Brawner (brawner@gmail.com) 
     Commit Version: 1.6.0-4-g7f85cfe  Build Version: 1.6.7995.38578
     For more information, please see http://wiki.ros.org/sw_urdf_exporter -->
<robot
  name="urdf6">
  <link
    name="base_link">
    
    <!--
    <inertial>
      <origin
        xyz="-6.89188785065771E-05 -7.24690796620213E-05 0.0304518795595389"
        rpy="0 0 0" />
      
    </inertial> -->
    
    <visual>
      <origin
        xyz="0 0 0"
        rpy="0 0 0" />
      <geometry>
        <mesh
          filename="package://urdf6/meshes/base_link.STL" />
      </geometry>
      <material
        name="">
        <color
          rgba="0.752941176470588 0.752941176470588 0.752941176470588 1" />
      </material>
    </visual>
    <collision>
      <origin
        xyz="0 0 0"
        rpy="0 0 0" />
      <geometry>
        <mesh
          filename="package://urdf6/meshes/base_link.STL" />
      </geometry>
    </collision>
  </link>
  <link
    name="link1">
    <inertial>
      <origin
        xyz="7.53309775940596E-06 0.0360054139595827 -0.000346559557670212"
        rpy="0 0 0" />
      <mass
        value="0.239773981452496" />
      <inertia
        ixx="7.74542298957872E-05"
        ixy="1.18444475290887E-08"
        ixz="3.48220049242199E-07"
        iyy="8.05660810459672E-05"
        iyz="4.40820601473184E-06"
        izz="0.000133033409701812" />
    </inertial>
    <visual>
      <origin
        xyz="0 0 0"
        rpy="0 0 0" />
      <geometry>
        <mesh
          filename="package://urdf6/meshes/link1.STL" />
      </geometry>
      <material
        name="">
        <color
          rgba="0.752941176470588 0.752941176470588 0.752941176470588 1" />
      </material>
    </visual>
    <collision>
      <origin
        xyz="0 0 0"
        rpy="0 0 0" />
      <geometry>
        <mesh
          filename="package://urdf6/meshes/link1.STL" />
      </geometry>
    </collision>
  </link>
  <joint
    name="joint1"
    type="continuous">
    <origin
      xyz="0 0 0.057"
      rpy="1.5707963267949 0 0" />
    <parent
      link="base_link" />
    <child
      link="link1" />
    <axis
      xyz="0 1 0" />
  </joint>
  <link
    name="link2">
    <inertial>
      <origin
        xyz="-0.150718238673013 -0.000522185237364858 -0.000294818652837585"
        rpy="0 0 0" />
      <mass
        value="0.751193993090721" />
      <inertia
        ixx="0.000285322998998329"
        ixy="2.74053761071855E-05"
        ixz="-2.66590351143892E-05"
        iyy="0.00307466790184105"
        iyz="-2.95121795793897E-07"
        izz="0.00330899103828553" />
    </inertial>
    <visual>
      <origin
        xyz="0 0 0"
        rpy="0 0 0" />
      <geometry>
        <mesh
          filename="package://urdf6/meshes/link2.STL" />
      </geometry>
      <material
        name="">
        <color
          rgba="0.752941176470588 0.752941176470588 0.752941176470588 1" />
      </material>
    </visual>
    <collision>
      <origin
        xyz="0 0 0"
        rpy="0 0 0" />
      <geometry>
        <mesh
          filename="package://urdf6/meshes/link2.STL" />
      </geometry>
    </collision>
  </link>
  <joint
    name="joint2"
    type="continuous">
    <origin
      xyz="0 0.0529999999999999 0"
      rpy="0 0 0" />
    <parent
      link="link1" />
    <child
      link="link2" />
    <axis
      xyz="0 0 1" />
  </joint>
  <link
    name="link3">
    <inertial>
      <origin
        xyz="0.133011478657982 0.0545925481011977 0.000779395568273772"
        rpy="0 0 0" />
      <mass
        value="0.312358588332606" />
      <inertia
        ixx="0.000361894289271901"
        ixy="-0.000107555013370869"
        ixz="2.98898566420583E-05"
        iyy="0.00194330301484136"
        iyz="2.59709746845096E-06"
        izz="0.00223530191844478" />
    </inertial>
    <visual>
      <origin
        xyz="0 0 0"
        rpy="0 0 0" />
      <geometry>
        <mesh
          filename="package://urdf6/meshes/link3.STL" />
      </geometry>
      <material
        name="">
        <color
          rgba="0.752941176470588 0.752941176470588 0.752941176470588 1" />
      </material>
    </visual>
    <collision>
      <origin
        xyz="0 0 0"
        rpy="0 0 0" />
      <geometry>
        <mesh
          filename="package://urdf6/meshes/link3.STL" />
      </geometry>
    </collision>
  </link>
  <joint
    name="joint3"
    type="continuous">
    <origin
      xyz="-0.27 0 0"
      rpy="0 0 0" />
    <parent
      link="link2" />
    <child
      link="link3" />
    <axis
      xyz="0 0 1" />
  </joint>
  <link
    name="link4">
    <inertial>
      <origin
        xyz="0.0587858457819843 -0.00289214497665843 0.00620683431201297"
        rpy="0 0 0" />
      <mass
        value="0.278926827428313" />
      <inertia
        ixx="5.18288069297991E-05"
        ixy="2.59726077407572E-06"
        ixz="7.75079677011625E-06"
        iyy="8.31265459243838E-05"
        iyz="-2.35921253114045E-06"
        izz="5.59587296971027E-05" />
    </inertial>
    <visual>
      <origin
        xyz="0 0 0"
        rpy="0 0 0" />
      <geometry>
        <mesh
          filename="package://urdf6/meshes/link4.STL" />
      </geometry>
      <material
        name="">
        <color
          rgba="0.752941176470588 0.752941176470588 0.752941176470588 1" />
      </material>
    </visual>
    <collision>
      <origin
        xyz="0 0 0"
        rpy="0 0 0" />
      <geometry>
        <mesh
          filename="package://urdf6/meshes/link4.STL" />
      </geometry>
    </collision>
  </link>
  <joint
    name="joint4"
    type="continuous">
    <origin
      xyz="0.27 0.0600000000000002 0"
      rpy="0 0 0" />
    <parent
      link="link3" />
    <child
      link="link4" />
    <axis
      xyz="0 0 1" />
  </joint>
  <link
    name="link5">
    <inertial>
      <origin
        xyz="0.0604420389458305 -0.00198748739617061 -6.81761220354485E-05"
        rpy="0 0 0" />
      <mass
        value="0.162243743001659" />
      <inertia
        ixx="0.000147580670961414"
        ixy="3.73230840893642E-07"
        ixz="2.19663714616664E-07"
        iyy="0.00011113444420312"
        iyz="-1.43666683887594E-07"
        izz="0.000109969803407873" />
    </inertial>
    <visual>
      <origin
        xyz="0 0 0"
        rpy="0 0 0" />
      <geometry>
        <mesh
          filename="package://urdf6/meshes/link5.STL" />
      </geometry>
      <material
        name="">
        <color
          rgba="0.752941176470588 0.752941176470588 0.752941176470588 1" />
      </material>
    </visual>
    <collision>
      <origin
        xyz="0 0 0"
        rpy="0 0 0" />
      <geometry>
        <mesh
          filename="package://urdf6/meshes/link5.STL" />
      </geometry>
    </collision>
  </link>
  <joint
    name="joint5"
    type="continuous">
    <origin
      xyz="0.0669999999999998 0 -0.00100000000000026"
      rpy="0 0 0" />
    <parent
      link="link4" />
    <child
      link="link5" />
    <axis
      xyz="0 1 0" />
  </joint>
  <link
    name="link6">
    <inertial>
      <origin
        xyz="0.0446202703277436 0.00504287281033167 -0.00051499292639693"
        rpy="0 0 0" />
      <mass
        value="0.17425078326966" />
      <inertia
        ixx="0.000183015378187362"
        ixy="2.6100426723293E-05"
        ixz="-9.65252302611167E-07"
        iyy="0.00029947909265242"
        iyz="1.20067701560423E-06"
        izz="0.000188224617813888" />
    </inertial>
    <visual>
      <origin
        xyz="0 0 0"
        rpy="0 0 0" />
      <geometry>
        <mesh
          filename="package://urdf6/meshes/gripper.STL" />
      </geometry>
      <material
        name="">
        <color
          rgba="0.752941176470588 0.752941176470588 0.752941176470588 1" />
      </material>
    </visual>
    <collision>
      <origin
        xyz="0 0 0"
        rpy="0 0 0" />
      <geometry>
        <mesh
          filename="package://urdf6/meshes/gripper.STL" />
      </geometry>
    </collision>
  </link>
  <joint
    name="joint6"
    type="continuous">
    <origin
      xyz="0.1749 0 0"
      rpy="-1.5708 0 0" />
    <parent
      link="link5" />
    <child
      link="link6" />
    <axis
      xyz="1 0 0" />
  </joint>
</robot>